<?xml version="1.0"?>
<robot xmlns:xacro="http://ros.org/wiki/xacro">

	<xacro:include filename="$(find complete_soft_hand)/model/materials.urdf.xacro"/>

	<xacro:property name="pi" value="3.1415926535897931" />
	<xacro:property name="abd_lb" value="-30" />
	<xacro:property name="abd_ub" value="30" />
	<xacro:property name="inner_lb" value="0" />
	<xacro:property name="inner_ub" value="45" />
	<xacro:property name="middle_lb" value="0" />
	<xacro:property name="middle_ub" value="45" />
	<xacro:property name="outer_lb" value="0" />
	<xacro:property name="outer_ub" value="45" />
	<xacro:property name="velocity" value="100" />
	<xacro:property name="effort" value="100" />


	<!-- Declaration of single finger that we can replicate in another position -->
	<!-- We suppose that 4th fingers are equal (index, middle, ring, little) -->

	<xacro:macro name="soft_finger" params="parent name position orientation">
		<!-- macro for one finger -->

		<!-- abductor joint between palm_link and finger_abd_link - fake between palm and proximal -->

		<!-- KNUCKLE -->
		<joint name="${name}_abd_joint" type="revolute">
			<origin xyz="${position}" rpy="${orientation}" />
			<parent link="${parent}"/>
			<child link="${name}_knuckle_link"/>
			<axis xyz="0 0 1" />
			<limit lower="${abd_lb *pi/180}" upper="${inner_ub *pi/180}" effort="${effort}" velocity="${velocity}"/>
		</joint>
		
		<link name="${name}_knuckle_link"> 
			<visual>
				<origin xyz="0 0 0" rpy="0 0 0" />
				<geometry>
					<mesh filename="package://complete_soft_hand/meshes/phalanx_prossimal_injection.stl" scale=" .001 .001 .001" />
				</geometry>
				<material name="DarkGolden" />
			</visual>
		</link>
		<!-- end KNUCKLE -->


		<!-- PHALANGE -->
		<!-- immaginary link-->
		<!-- joint and link FAKE 1-->
		<joint name="${name}_inner_joint
" type="revolute">
			<origin xyz="-0.009 0 0" rpy="0 0 0" />
			<parent link="${name}_knuckle_link"/>
			<child link="${name}_inner_link

"/>
			<axis xyz="0 1 0" />
			<limit lower="${inner_lb *pi/180}" upper="${inner_ub *pi/180}" effort="${effort}" velocity="${velocity}"/>
		</joint>

		<link name="${name}_inner_link

"> 
		</link> 
		<!-- end immaginary link-->
		
		<!-- abductor joint between palm_link and finger_abd_link - fake between palm and proximal -->
		<joint name="${name}_inner_joint" type="revolute">
			<origin xyz="-0.013 0 0" rpy="0 0 0" />
			<parent link="${name}_inner_link

"/>
			<child link="${name}_proximal_link"/>
			<axis xyz="0 1 0" />
			<mimic joint="${name}_inner_joint
" multiplier="1" />
			<limit lower="${middle_lb *pi/180}" upper="${middle_ub *pi/180}" effort="${effort}" velocity="${velocity}"/>
		</joint>

		<link name="${name}_proximal_link"> 
			<visual>
				<origin xyz="0 0 0" rpy="0 0 0" />
				<geometry>
					<mesh filename="package://complete_soft_hand/meshes/phalanx_short_injection.stl" scale=" .001 .001 .001" />
				</geometry>
				<material name="DarkGolden" />
			</visual>
		</link>
		<!-- end PHALANGE -->


		<!-- LITTLE PHALANGE -->
		<!-- immaginary link-->
		<!-- joint and link FAKE 2-->
		<joint name="${name}_middle_joint

" type="revolute">
			<origin xyz="-0.009 0 0" rpy="0 0 0" />
			<parent link="${name}_proximal_link"/>
			<child link="${name}_fake_link2"/>
			<axis xyz="0 1 0" />
			<limit lower="${inner_lb *pi/180}" upper="${inner_ub *pi/180}" effort="${effort}" velocity="${velocity}"/>
		</joint>

		<link name="${name}_fake_link2"> 
		</link> 
		<!-- end immaginary link-->

		<joint name="${name}_middle_joint" type="revolute">
			<origin xyz="-0.013 0 0" rpy="0 0 0" />
			<parent link="${name}_fake_link2"/>
			<child link="${name}_middle_link"/>
			<axis xyz="0 1 0" />
			<mimic joint="${name}_middle_joint

" multiplier="1" />
			<limit lower="${outer_lb *pi/180}" upper="${outer_ub *pi/180}" effort="${effort}" velocity="${velocity}"/>
		</joint>
		<link name="${name}_middle_link"> 
			<visual>
				<origin xyz="0 0 0" rpy="0 0 0" />
				<geometry>
					<mesh filename="package://complete_soft_hand/meshes/phalanx_short_injection.stl" scale=" .001 .001 .001" />
				</geometry>
				<material name="DarkGolden" />
			</visual>
		</link>
		<!-- end LITTLE PHALANGE -->


		<!-- BABY PHALANGE -->
		<!-- immaginary link-->
		<!-- joint and link FAKE 3-->
		<joint name="${name}_outer_joint
" type="revolute">
			<origin xyz="-0.009 0 0" rpy="0 0 0" />
			<parent link="${name}_middle_link"/>
			<child link="${name}_fake_link3"/>
			<axis xyz="0 1 0" />
			<limit lower="${inner_lb *pi/180}" upper="${inner_ub *pi/180}" effort="${effort}" velocity="${velocity}"/>
		</joint>

		<link name="${name}_fake_link3"> 
		</link> 
		<!-- end immaginary link-->

		<joint name="${name}_outer_joint" type="revolute">
			<origin xyz="-0.013 0 0" rpy="0 0 0" />
			<parent link="${name}_fake_link3"/>
			<child link="${name}_distal_link"/>
			<axis xyz="0 1 0" />
			<mimic joint="${name}_outer_joint
" multiplier="1" />
			<limit lower="${inner_lb *pi/180}" upper="${inner_ub *pi/180}" effort="${effort}" velocity="${velocity}"/>
		</joint>
		<link name="${name}_distal_link"> 
			<visual>
				<origin xyz="0 0 0" rpy="0 0 0" />
				<geometry>
					<mesh filename="package://complete_soft_hand/meshes/phalanx_distal_out_no_ati.stl" scale=" .001 .001 .001" />
				</geometry>
				<material name="DarkGolden" />
			</visual>
		</link>
		<!-- end BABY PHALANGE -->
	</xacro:macro>
	
	<!-- end FINGER model -->


	<!-- THUMB model -->

	<xacro:macro name="thumb_finger" params="parent name position orientation">
		<!-- macro for one finger -->

		<!-- abductor joint between palm_link and thumb_abd_link - fake between palm and proximal -->

		<!-- THUMB KNUCKLE -->
		<joint name="${name}_abd_joint" type="revolute">
			<origin xyz="${position}" rpy="${orientation}" />
			<parent link="${parent}"/>
			<child link="${name}_knuckle_link"/>
			<axis xyz="0 1 0" />
			<limit lower="${-2*inner_ub *pi/180}" upper="${inner_lb *pi/180}" effort="${effort}" velocity="${velocity}"/>
		</joint>
		
		<link name="${name}_knuckle_link"> 
			<visual>
				<origin xyz="0 0 0" rpy="0 0 0" />
				<geometry>
					<mesh filename="package://complete_soft_hand/meshes/phalanx_thumb_injection.stl" scale=" .001 .001 .001" />
				</geometry>
				<material name="DarkGolden" />
			</visual>
		</link>
		<!-- end KNUCKLE -->


		<!-- THUMB PHALANGE -->
		<!-- immaginary link-->
		<!-- joint and link FAKE 1-->
		<joint name="${name}_inner_joint
" type="revolute">
			<origin xyz="-0.0225 0 -0.0033" rpy="-1.9974238811 0 0" />
			<parent link="${name}_knuckle_link"/>
			<child link="${name}_inner_link

"/>
			<axis xyz="0 1 0" />
			<limit lower="${inner_lb *pi/180}" upper="${inner_ub *pi/180}" effort="${effort}" velocity="${velocity}"/>
		</joint>

		<link name="${name}_inner_link

"> 
		</link> 
		<!-- end immaginary link-->
		
		<!-- abductor joint between palm_link and finger_abd_link - fake between palm and proximal -->
		<joint name="${name}_inner_joint" type="revolute">
			<origin xyz="-0.013 0 0" rpy="0 0 0" />
			<parent link="${name}_inner_link

"/>
			<child link="${name}_proximal_link"/>
			<axis xyz="0 1 0" />
			<mimic joint="${name}_inner_joint
" multiplier="1" />
			<limit lower="${middle_lb *pi/180}" upper="${middle_ub *pi/180}" effort="${effort}" velocity="${velocity}"/>
		</joint>

		<link name="${name}_proximal_link"> 
			<visual>
				<origin xyz="0 0 0" rpy="0 0 0" />
				<geometry>
					<mesh filename="package://complete_soft_hand/meshes/phalanx_short_injection.stl" scale=" .001 .001 .001" />
				</geometry>
				<material name="DarkGolden" />
			</visual>
		</link>
		<!-- end PHALANGE -->


		<!-- THUMB LITTLE PHALANGE -->
		<!-- immaginary link-->
		<!-- joint and link FAKE 2-->
		<joint name="${name}_middle_joint

" type="revolute">
			<origin xyz="-0.009 0 0" rpy="0 0 0" />
			<parent link="${name}_proximal_link"/>
			<child link="${name}_fake_link2"/>
			<axis xyz="0 1 0" />
			<limit lower="${inner_lb *pi/180}" upper="${inner_ub *pi/180}" effort="${effort}" velocity="${velocity}"/>
		</joint>

		<link name="${name}_fake_link2"> 
		</link> 
		<!-- end immaginary link-->

		<joint name="${name}_middle_joint" type="revolute">
			<origin xyz="-0.013 0 0" rpy="0 0 0" />
			<parent link="${name}_fake_link2"/>
			<child link="${name}_middle_link"/>
			<axis xyz="0 1 0" />
			<mimic joint="${name}_middle_joint

" multiplier="1" />
			<limit lower="${outer_lb *pi/180}" upper="${outer_ub *pi/180}" effort="${effort}" velocity="${velocity}"/>
		</joint>
		<link name="${name}_middle_link"> 
			<visual>
				<origin xyz="0 0 0" rpy="0 0 0" />
				<geometry>
					<mesh filename="package://complete_soft_hand/meshes/phalanx_short_injection.stl" scale=" .001 .001 .001" />
				</geometry>
				<material name="DarkGolden" />
			</visual>
		</link>


		<!-- THUMB BABY PHALANGE -->
		<!-- immaginary link-->
		<!-- joint and link FAKE 3-->
		<joint name="${name}_outer_joint
" type="revolute">
			<origin xyz="-0.009 0 0.0" rpy="0 0 0" />
			<parent link="${name}_middle_link"/>
			<child link="${name}_fake_link3"/>
			<axis xyz="0 1 0" />
			<limit lower="${inner_lb *pi/180}" upper="${inner_ub *pi/180}" effort="${effort}" velocity="${velocity}"/>
		</joint>

		<link name="${name}_fake_link3"> 
		</link> 
		<!-- end immaginary link-->

		<joint name="${name}_outer_joint" type="revolute">
			<origin xyz="-0.013 0 0" rpy="0 0 0" />
			<parent link="${name}_fake_link3"/>
			<child link="${name}_distal_link"/>
			<axis xyz="0 1 0" />
			<mimic joint="${name}_outer_joint
" multiplier="1" />
			<limit lower="${inner_lb *pi/180}" upper="${inner_ub *pi/180}" effort="${effort}" velocity="${velocity}"/>
		</joint>
		<link name="${name}_distal_link"> 
			<visual>
				<origin xyz="0 0 0" rpy="0 0 0" />
				<geometry>
					<mesh filename="package://complete_soft_hand/meshes/phalanx_distal_out_no_ati.stl" scale=" .001 .001 .001" />
				</geometry>
				<material name="DarkGolden" />
			</visual>
		</link>
		<!-- end BABY PHALANGE -->


	</xacro:macro>
	<!-- end THUMB model -->


	<xacro:macro name="complete_soft_hand" params="parent name *origin">
		<!-- macro for the hand -->

		<!-- PALM -->
		<joint name="${name}_palm_joint" type="fixed" >
			<origin xyz="0 0 0" rpy="0 0 0" />
			<parent link="${parent}" />
			<child link="${name}_palm_link" />
			<!-- <axis xyz="0 1 0" /> -->
			<!-- <limit lower="${-90*pi/180}" upper="${90*pi/180}" effort="${effort}" velocity="${velocity}"/> -->
		</joint>

		<link name="${name}_palm_link">
			<visual>
				<origin xyz="0 0 0" rpy="0 0 0" />
				<geometry>
					<mesh filename="package://complete_soft_hand/meshes/palm_hand.stl" scale=" .001 .001 .001" /> 
				</geometry>
				<material name="LightGrey" />
			</visual>
		</link>

		<!-- end PALM -->
		

		
		<!-- macro for each finger -->

		<xacro:thumb_finger parent="${name}_palm_link" name="${name}_thumb" position="-0.0418769 0.0538740 -0.00691972	" orientation="0 0 -0.43633181" />
		<xacro:soft_finger parent="${name}_palm_link" name="${name}_index" position="-0.0285 0.0943918 0.00205" orientation="${180*pi/180} 0 ${(-90+20)*pi/180}" />
		<xacro:soft_finger parent="${name}_palm_link" name="${name}_middle" position="-0.009 0.107892 0.00205" orientation="${180*pi/180} 0 ${-90*pi/180}" />
		<xacro:soft_finger parent="${name}_palm_link" name="${name}_ring" position="0.0105 0.0943918 0.00205" orientation="${180*pi/180} 0 ${(-90-10)*pi/180}" />
		<xacro:soft_finger parent="${name}_palm_link" name="${name}_little" position="0.030 0.0808918 0.00205" orientation="${180*pi/180} 0 ${(-90-20)*pi/180}" />
		
	</xacro:macro>

</robot>
