<?xml version="1.0"?>
<robot xmlns:xacro="http://ros.org/wiki/xacro">

	<!--
		HAND MODEL v.01
		Material: ABS 
		CAD model available at: http://www.naturalmachinemotioninitiative.com/#!softhand/c24r2
	-->

	<xacro:include filename="$(find soft_hand_description)/model/materials.urdf.xacro"/>
	<xacro:include filename="$(find soft_hand_description)/model/soft_hand.transmission.xacro"/>
	<xacro:include filename="$(find soft_hand_description)/model/soft_hand.gazebo.xacro"/>
	<xacro:include filename="$(find soft_hand_description)/model/soft_hand.inertia.xacro"/>

	<xacro:property name="pi" value="3.1415926535897931" />

	<!-- joint properties -->
	<xacro:property name="abd_lb" value="-30" />
	<xacro:property name="abd_ub" value="30" />
	<xacro:property name="thumb_abd_lb" value="0" />
	<xacro:property name="thumb_abd_ub" value="90" />
	<xacro:property name="inner_lb" value="0" />
	<xacro:property name="inner_ub" value="45" />
	<xacro:property name="middle_lb" value="0" />
	<xacro:property name="middle_ub" value="45" />
	<xacro:property name="outer_lb" value="0" />
	<xacro:property name="outer_ub" value="45" />
	<xacro:property name="velocity" value="100" />
	<xacro:property name="effort" value="100" />
	<xacro:property name="damping" value="0.0" />
	<xacro:property name="friction" value="0.0" />

	<!-- synergy vector -->
	<xacro:property name="thumb_abd_R" value="1.3" />
	<xacro:property name="thumb_inner_R" value="1.3" />
	<xacro:property name="thumb_outer_R" value="1.0" />
	<xacro:property name="index_abd_R" value="-0.2" />
	<xacro:property name="index_inner_R" value="1.0" />
	<xacro:property name="index_middle_R" value="1.0" />
	<xacro:property name="index_outer_R" value="1.0" />
	<xacro:property name="middle_abd_R" value="0.0" />
	<xacro:property name="middle_inner_R" value="1.0" />
	<xacro:property name="middle_middle_R" value="1.0" />
	<xacro:property name="middle_outer_R" value="1.0" />
	<xacro:property name="ring_abd_R" value="0.2" />
	<xacro:property name="ring_inner_R" value="1.0" />
	<xacro:property name="ring_middle_R" value="1.0" />
	<xacro:property name="ring_outer_R" value="1.0" />
	<xacro:property name="little_abd_R" value="0.4" />
	<xacro:property name="little_inner_R" value="1.0" />
	<xacro:property name="little_middle_R" value="1.0" />
	<xacro:property name="little_outer_R" value="1.0" />

	<!-- synergy joint properties -->
	<xacro:property name="synergy_lb" value="0.0" />
	<xacro:property name="synergy_ub" value="1.0" />
	<xacro:property name="max_synergy_velocity" value="100" />
	<xacro:property name="max_synergy_effort" value="100" />
	<xacro:property name="synergy_damping" value="0.0" />
	<xacro:property name="synergy_friction" value="0.0" />

	<!-- SOFT FINGER model -->
	<!-- 4 fingers are equal (index, middle, ring, little) -->
	<xacro:macro name="soft_finger" params="parent name position orientation useMimicTag abd_R inner_R middle_R outer_R">

		<!-- KNUCKLE -->
		<joint name="${name}_abd_joint" type="revolute">
			<origin xyz="${position}" rpy="${orientation}" />
			<parent link="${parent}"/>
			<child link="${name}_knuckle_link"/>
			<axis xyz="0 0 1" />
			<limit lower="${abd_lb *pi/180}" upper="${abd_ub *pi/180}" effort="${effort}" velocity="${velocity}"/>
			<dynamics damping="${damping}" friction="${friction}"/>
			<xacro:if value="${useMimicTag}">
				<mimic joint="synergy_joint" multiplier="${abd_R}"/>
			</xacro:if>
		</joint>
		
		<link name="${name}_knuckle_link">
			<inertial>
				<insert_block name="knuckle_inertia"/>
			</inertial>
			<visual>
				<origin xyz="0 0 0" rpy="0 0 0" />
				<geometry>
					<mesh filename="package://soft_hand_description/meshes/knuckle.stl" scale=" .001 .001 .001" />
				</geometry>
				<material name="SoftHand/DarkGolden" />
			</visual>
			<collision>
				<!-- origin xyz="-0.001 0.0 0.001" rpy="0 0 0" /-->
				<geometry>
					<!-- box size="0.034 0.014 0.024"/-->
					<mesh filename="package://soft_hand_description/meshes/knuckle.stl" scale=" .001 .001 .001" />
				</geometry>
			</collision>
		</link>

		<!-- PROXIMAL PHALANGE -->
		<joint name="${name}_inner_joint" type="revolute">
			<origin xyz="-0.009 0 0" rpy="0 0 0" />
			<parent link="${name}_knuckle_link"/>
			<child link="${name}_fake_link1"/>
			<axis xyz="0 1 0" />
			<limit lower="${inner_lb *pi/180}" upper="${inner_ub *pi/180}" effort="${effort}" velocity="${velocity}"/>
			<dynamics damping="${damping}" friction="${friction}"/>
			<xacro:if value="${useMimicTag}">
				<mimic joint="synergy_joint" multiplier="${inner_R}"/>
			</xacro:if>
		</joint>

		<link name="${name}_fake_link1">
			<inertial>
				<insert_block name="negligible_inertia"/>
			</inertial>
		</link>

		<joint name="${name}_inner_joint_mimic" type="revolute">
			<origin xyz="-0.013 0 0" rpy="0 0 0" />
			<parent link="${name}_fake_link1"/>
			<child link="${name}_proximal_link"/>
			<axis xyz="0 1 0" />
			<limit lower="${inner_lb *pi/180}" upper="${inner_ub *pi/180}" effort="${effort}" velocity="${velocity}"/>
			<dynamics damping="${damping}" friction="${friction}"/>
			<xacro:if value="${useMimicTag}">
				<mimic joint="synergy_joint" multiplier="${inner_R}" />
			</xacro:if>
		</joint>

		<link name="${name}_proximal_link">
			<inertial>
				<insert_block name="phalanx_inertia"/>
			</inertial>
			<visual>
				<origin xyz="0 0 0" rpy="0 0 0" />
				<geometry>
					<mesh filename="package://soft_hand_description/meshes/phalanx.stl" scale=" .001 .001 .001" />
				</geometry>
				<material name="SoftHand/DarkGolden" />
			</visual>
			<collision>
				<!-- origin xyz="-0.005 0.0 0.0 " rpy="0 0 0" /-->
				<geometry>
					<!-- box size="0.025 0.014 0.019"/-->
					<mesh filename="package://soft_hand_description/meshes/phalanx.stl" scale=" .001 .001 .001" />
				</geometry>
			</collision>
		</link>

		<!-- MIDDLE PHALANGE -->
		<joint name="${name}_middle_joint" type="revolute">
			<origin xyz="-0.009 0 0" rpy="0 0 0" />
			<parent link="${name}_proximal_link"/>
			<child link="${name}_fake_link2"/>
			<axis xyz="0 1 0" />
			<limit lower="${middle_lb *pi/180}" upper="${middle_ub *pi/180}" effort="${effort}" velocity="${velocity}"/>
			<dynamics damping="${damping}" friction="${friction}"/>
			<xacro:if value="${useMimicTag}">
				<mimic joint="synergy_joint" multiplier="${middle_R}"/>
			</xacro:if>
		</joint>

		<link name="${name}_fake_link2">
			<inertial>
				<insert_block name="negligible_inertia"/>
			</inertial>
		</link>

		<joint name="${name}_middle_joint_mimic" type="revolute">
			<origin xyz="-0.013 0 0" rpy="0 0 0" />
			<parent link="${name}_fake_link2"/>
			<child link="${name}_middle_link"/>
			<axis xyz="0 1 0" />
			<limit lower="${middle_lb *pi/180}" upper="${middle_ub *pi/180}" effort="${effort}" velocity="${velocity}"/>
			<dynamics damping="${damping}" friction="${friction}"/>
			<xacro:if value="${useMimicTag}">
				<mimic joint="synergy_joint" multiplier="${middle_R}"/>
			</xacro:if>
		</joint>
		<link name="${name}_middle_link">
			<inertial>
				<insert_block name="phalanx_inertia"/>
			</inertial>
			<visual>
				<origin xyz="0 0 0" rpy="0 0 0" />
				<geometry>
					<mesh filename="package://soft_hand_description/meshes/phalanx.stl" scale=" .001 .001 .001" />
				</geometry>
				<material name="SoftHand/DarkGolden" />
			</visual>
			<collision>
				<geometry>
					<mesh filename="package://soft_hand_description/meshes/phalanx.stl" scale=" .001 .001 .001" />
				</geometry>
			</collision>
		</link>

		<!-- DISTAL PHALANGE -->
		<joint name="${name}_outer_joint" type="revolute">
			<origin xyz="-0.009 0 0" rpy="0 0 0" />
			<parent link="${name}_middle_link"/>
			<child link="${name}_fake_link3"/>
			<axis xyz="0 1 0" />
			<limit lower="${outer_lb *pi/180}" upper="${outer_ub *pi/180}" effort="${effort}" velocity="${velocity}"/>
			<dynamics damping="${damping}" friction="${friction}"/>
			<xacro:if value="${useMimicTag}">
				<mimic joint="synergy_joint" multiplier="${outer_R}"/>
			</xacro:if>
		</joint>

		<link name="${name}_fake_link3">
			<inertial>
				<insert_block name="negligible_inertia"/>
			</inertial>
		</link>

		<joint name="${name}_outer_joint_mimic" type="revolute">
			<origin xyz="-0.013 0 0" rpy="0 0 0" />
			<parent link="${name}_fake_link3"/>
			<child link="${name}_distal_link"/>
			<axis xyz="0 1 0" />
			<limit lower="${outer_lb *pi/180}" upper="${outer_ub *pi/180}" effort="${effort}" velocity="${velocity}"/>
			<dynamics damping="${damping}" friction="${friction}"/>
			<xacro:if value="${useMimicTag}">
				<mimic joint="synergy_joint" multiplier="${outer_R}"/>
			</xacro:if>
		</joint>
		<link name="${name}_distal_link">
			<inertial>
				<insert_block name="fingertip_inertia"/>
			</inertial>
			<visual>
				<origin xyz="0 0 0" rpy="0 0 0" />
				<geometry>
					<mesh filename="package://soft_hand_description/meshes/fingertip.stl" scale=" .001 .001 .001" />
				</geometry>
				<material name="SoftHand/DarkGolden" />
			</visual>
			<collision>
				<geometry>
					<mesh filename="package://soft_hand_description/meshes/fingertip.stl" scale=" .001 .001 .001" />
				</geometry>
			</collision>
		</link>

	</xacro:macro>

	<!-- THUMB MODEL -->
	<!-- It has one joint less than rest of fingers -->
	<xacro:macro name="soft_thumb" params="parent name position orientation useMimicTag abd_R inner_R outer_R">

		<!-- KNUCKLE -->
		<joint name="${name}_abd_joint" type="revolute">
			<origin xyz="${position}" rpy="${orientation}" />
			<parent link="${parent}"/>
			<child link="${name}_knuckle_link"/>
			<axis xyz="0 -1 0" />
			<limit lower="${thumb_abd_lb *pi/180}" upper="${thumb_abd_ub *pi/180}" effort="${effort}" velocity="${velocity}"/>
			<dynamics damping="${damping}" friction="${friction}"/>
			<xacro:if value="${useMimicTag}">
				<mimic joint="synergy_joint" multiplier="${abd_R}"/>
			</xacro:if>
		</joint>
		
		<link name="${name}_knuckle_link">
			<inertial>
				<insert_block name="thumb_knuckle_inertia"/>
			</inertial>
			<visual>
				<origin xyz="0 0 0" rpy="0 0 0" />
				<geometry>
					<mesh filename="package://soft_hand_description/meshes/thumb_knuckle.stl" scale=" .001 .001 .001" />
				</geometry>
				<material name="SoftHand/DarkGolden" />
			</visual>
			<collision>
				<geometry>
					<mesh filename="package://soft_hand_description/meshes/thumb_knuckle.stl" scale=" .001 .001 .001" />
				</geometry>
			</collision>
		</link>
		
		<!-- PROXIMAL PHALANGE -->
		<joint name="${name}_inner_joint" type="revolute">
			<origin xyz="-0.0225 0 -0.0033" rpy="-1.9974238811 0 0" />
			<parent link="${name}_knuckle_link"/>
			<child link="${name}_fake_link1"/>
			<axis xyz="0 1 0" />
			<limit lower="${inner_lb *pi/180}" upper="${inner_ub *pi/180}" effort="${effort}" velocity="${velocity}"/>
			<dynamics damping="${damping}" friction="${friction}"/>
			<xacro:if value="${useMimicTag}">
				<mimic joint="synergy_joint" multiplier="${inner_R}"/>
			</xacro:if>
		</joint>

		<link name="${name}_fake_link1">
			<inertial>
				<insert_block name="negligible_inertia"/>
			</inertial>
		</link>

		<joint name="${name}_inner_joint_mimic" type="revolute">
			<origin xyz="-0.013 0 0" rpy="0 0 0" />
			<parent link="${name}_fake_link1"/>
			<child link="${name}_proximal_link"/>
			<axis xyz="0 1 0" />
			<limit lower="${inner_lb *pi/180}" upper="${inner_ub *pi/180}" effort="${effort}" velocity="${velocity}"/>
			<dynamics damping="${damping}" friction="${friction}"/>
			<xacro:if value="${useMimicTag}">
				<mimic joint="synergy_joint" multiplier="${inner_R}" />
			</xacro:if>
		</joint>

		<link name="${name}_proximal_link">
			<inertial>
				<insert_block name="phalanx_inertia"/>
			</inertial>
			<visual>
				<origin xyz="0 0 0" rpy="0 0 0" />
				<geometry>
					<mesh filename="package://soft_hand_description/meshes/phalanx.stl" scale=" .001 .001 .001" />
				</geometry>
				<material name="SoftHand/DarkGolden" />
			</visual>
			<collision>
				<geometry>
					<mesh filename="package://soft_hand_description/meshes/phalanx.stl" scale=" .001 .001 .001" />
				</geometry>
			</collision>
		</link>

		<!-- DISTAL PHALANGE -->
		<joint name="${name}_outer_joint" type="revolute">
			<origin xyz="-0.009 0 0.0" rpy="0 0 0" />
			<parent link="${name}_proximal_link"/>
			<child link="${name}_fake_link3"/>
			<axis xyz="0 1 0" />
			<limit lower="${outer_lb *pi/180}" upper="${outer_ub *pi/180}" effort="${effort}" velocity="${velocity}"/>
			<dynamics damping="${damping}" friction="${friction}"/>
			<xacro:if value="${useMimicTag}">
				<mimic joint="synergy_joint" multiplier="${outer_R}"/>
			</xacro:if>
		</joint>

		<link name="${name}_fake_link3">
			<inertial>
				<insert_block name="negligible_inertia"/>
			</inertial>
		</link>

		<joint name="${name}_outer_joint_mimic" type="revolute">
			<origin xyz="-0.013 0 0" rpy="0 0 0" />
			<parent link="${name}_fake_link3"/>
			<child link="${name}_distal_link"/>
			<axis xyz="0 1 0" />
			<limit lower="${outer_lb *pi/180}" upper="${outer_ub *pi/180}" effort="${effort}" velocity="${velocity}"/>
			<dynamics damping="${damping}" friction="${friction}"/>
			<xacro:if value="${useMimicTag}">
				<mimic joint="synergy_joint" multiplier="${outer_R}" />
			</xacro:if>
		</joint>
		<link name="${name}_distal_link">
			<inertial>
				<insert_block name="fingertip_inertia"/>
			</inertial>
			<visual>
				<origin xyz="0 0 0" rpy="0 0 0" />
				<geometry>
					<mesh filename="package://soft_hand_description/meshes/fingertip.stl" scale=" .001 .001 .001" />
				</geometry>
				<material name="SoftHand/DarkGolden" />
			</visual>
			<collision>
				<geometry>
					<mesh filename="package://soft_hand_description/meshes/fingertip.stl" scale=" .001 .001 .001" />
				</geometry>
			</collision>
		</link>

	</xacro:macro>

	<!-- SOFT HAND MODEL -->
	<xacro:macro name="soft_hand" params="parent name withAdaptiveTransmission useMimicTag *origin">

		<!-- MOTOR JOINT -->
		<joint name="synergy_joint" type="revolute" >
			<parent link="${parent}" />
			<child link="invisible_wire_link"/>
			<axis xyz="0 0 1" />
			<limit lower="${synergy_lb}" upper="${synergy_ub}" effort="${max_synergy_effort}" velocity="${max_synergy_velocity}"/>
			<dynamics damping="${synergy_damping}" friction="${synergy_friction}"/>
		</joint>
		<link name="invisible_wire_link">
			<inertial>
				<insert_block name="negligible_inertia"/>
			</inertial>
		</link>

		<!-- PALM -->
		<joint name="${name}_palm_joint" type="fixed" >
			<insert_block name="origin"/>
			<parent link="${parent}" />
			<child link="${name}_palm_link" />
		</joint>

		<link name="${name}_palm_link">
			<inertial>
				<insert_block name="palm_inertia"/>
			</inertial>
			<visual>
				<origin xyz="0 0 0" rpy="0 0 0" />
				<geometry>
					<mesh filename="package://soft_hand_description/meshes/palm.stl" scale=" .001 .001 .001" />
				</geometry>
				<material name="SoftHand/LightGrey" />
			</visual>
			<collision>
				<geometry>
					<mesh filename="package://soft_hand_description/meshes/palm.stl" scale=" .001 .001 .001" />
				</geometry>
			</collision>
		</link>

		<!-- THUMB AND FINGERS -->
		<xacro:soft_thumb parent="${name}_palm_link" name="${name}_thumb" position="-0.0418769 0.0538740 -0.00691972" orientation="0 0 -0.43633181" useMimicTag="${useMimicTag}" abd_R="${thumb_abd_R *(thumb_abd_ub - thumb_abd_lb)*pi/180}" inner_R="${thumb_inner_R *(inner_ub - inner_lb)*pi/180}" outer_R="${thumb_outer_R *(outer_ub - outer_lb)*pi/180}"/>

		<xacro:soft_finger parent="${name}_palm_link" name="${name}_index" position="-0.0285 0.0943918 0.00205" orientation="${180*pi/180} 0 ${(-90+20)*pi/180}" useMimicTag="${useMimicTag}" abd_R="${index_abd_R}" inner_R="${index_inner_R *(inner_ub - inner_lb)*pi/180}" middle_R="${index_middle_R *(middle_ub - middle_lb)*pi/180}" outer_R="${index_outer_R *(outer_ub - outer_lb)*pi/180}" />

		<xacro:soft_finger parent="${name}_palm_link" name="${name}_middle" position="-0.009 0.107892 0.00205" orientation="${180*pi/180} 0 ${-90*pi/180}" useMimicTag="${useMimicTag}" abd_R="${middle_abd_R}" inner_R="${middle_inner_R *(inner_ub - inner_lb)*pi/180}" middle_R="${middle_middle_R *(middle_ub - middle_lb)*pi/180}" outer_R="${middle_outer_R *(outer_ub - outer_lb)*pi/180}" />

		<xacro:soft_finger parent="${name}_palm_link" name="${name}_ring" position="0.0105 0.0943918 0.00205" orientation="${180*pi/180} 0 ${(-90-10)*pi/180}" useMimicTag="${useMimicTag}" abd_R="${ring_abd_R}" inner_R="${ring_inner_R *(inner_ub - inner_lb)*pi/180}" middle_R="${ring_middle_R *(middle_ub - middle_lb)*pi/180}" outer_R="${ring_outer_R *(outer_ub - outer_lb)*pi/180}" />

		<xacro:soft_finger parent="${name}_palm_link" name="${name}_little" position="0.030 0.0808918 0.00205" orientation="${180*pi/180} 0 ${(-90-20)*pi/180}" useMimicTag="${useMimicTag}" abd_R="${little_abd_R}" inner_R="${little_inner_R *(inner_ub - inner_lb)*pi/180}" middle_R="${little_middle_R *(middle_ub - middle_lb)*pi/180}" outer_R="${little_outer_R *(outer_ub - outer_lb)*pi/180}" />

		<xacro:soft_hand_transmission name="${name}" withAdaptiveTransmission="${withAdaptiveTransmission}"/>
		<xacro:soft_hand_gazebo name="${name}" withAdaptiveTransmission="${withAdaptiveTransmission}"/>
		
	</xacro:macro>

</robot>